output.txt

Processing started at: 2023-11-07 22:45:34.451097
book: book-1
 Buy -- Sell
==================================
49@100.00 -- 33@100.10
97@100.00 -- 20@100.20
38@100.00 -- 37@100.30
63@99.90 -- 7@100.30
10@99.80 -- 97@100.40
40@99.70 -- 4@100.40
42@99.70 -- 85@100.40
51@99.70 -- 41@100.40
9@99.60 -- 59@100.40
89@99.60 -- 16@100.50
92@99.50 -- 30@100.60
61@99.50 -- 59@100.70
18@99.50 -- 41@100.80
74@99.40 -- 49@100.80
59@99.40 -- 30@100.90
93@99.40 -- 42@101.30
16@99.30 -- 32@101.60
92@99.10 -- 
6@99.10 -- 
54@98.80 -- 


book: book-2
 Buy -- Sell
==================================
1@99.90 -- 3@100.00
1@99.80 -- 15@100.00
60@99.80 -- 21@100.20
30@99.70 -- 57@100.20
2@99.70 -- 59@100.20
32@99.70 -- 13@100.20
1@99.70 -- 89@100.20
85@99.70 -- 9@100.20
14@99.70 -- 12@100.20
2@99.60 -- 28@100.20
4@99.60 -- 12@100.30
14@99.60 -- 33@100.30
65@99.60 -- 93@100.30
83@99.50 -- 56@100.40
11@99.50 -- 10@100.60
37@99.50 -- 65@100.60
48@99.40 -- 77@100.60
35@99.40 -- 67@100.60
86@99.10 -- 28@100.60
57@98.70 -- 50@100.60
 -- 69@101.00
 -- 25@101.20


book: book-3
 Buy -- Sell
==================================
33@100.10 -- 90@100.20
44@100.00 -- 45@100.30
47@99.90 -- 34@100.30
56@99.90 -- 51@100.30
58@99.90 -- 4@100.40
49@99.80 -- 25@100.40
8@99.80 -- 32@100.50
38@99.80 -- 62@100.50
20@99.80 -- 36@100.50
15@99.70 -- 19@100.60
64@99.70 -- 45@100.60
7@99.70 -- 85@100.70
20@99.60 -- 96@100.70
99@99.60 -- 94@100.90
71@99.50 -- 28@100.90
93@99.40 -- 67@100.90
41@99.20 -- 69@101.10
30@99.20 -- 
6@99.20 -- 
75@99.10 -- 
5@99.00 -- 


Processing completed at: 2023-11-07 22:46:00.628306
Processing Duration: 0:00:26.177156



// Multithreaded approach

Processing started at: 2023-11-07 22:46:11.355438
book: book-1
 Buy -- Sell
==================================
49@100.00 -- 33@100.10
97@100.00 -- 20@100.20
38@100.00 -- 37@100.30
63@99.90 -- 7@100.30
10@99.80 -- 97@100.40
40@99.70 -- 4@100.40
42@99.70 -- 85@100.40
51@99.70 -- 41@100.40
9@99.60 -- 59@100.40
89@99.60 -- 16@100.50
92@99.50 -- 30@100.60
61@99.50 -- 59@100.70
18@99.50 -- 41@100.80
74@99.40 -- 49@100.80
59@99.40 -- 30@100.90
93@99.40 -- 42@101.30
16@99.30 -- 32@101.60
92@99.10 -- 
6@99.10 -- 
54@98.80 -- 

book: book-2
 Buy -- Sell
==================================
1@99.90 -- 3@100.00
1@99.80 -- 15@100.00
60@99.80 -- 21@100.20
30@99.70 -- 57@100.20
2@99.70 -- 59@100.20
32@99.70 -- 13@100.20
1@99.70 -- 89@100.20
85@99.70 -- 9@100.20
14@99.70 -- 12@100.20
2@99.60 -- 28@100.20
4@99.60 -- 12@100.30
14@99.60 -- 33@100.30
65@99.60 -- 93@100.30
83@99.50 -- 56@100.40
11@99.50 -- 10@100.60
37@99.50 -- 65@100.60
48@99.40 -- 77@100.60
35@99.40 -- 67@100.60
86@99.10 -- 28@100.60
57@98.70 -- 50@100.60
 -- 69@101.00
 -- 25@101.20

book: book-3
 Buy -- Sell
==================================
33@100.10 -- 90@100.20
44@100.00 -- 45@100.30
47@99.90 -- 34@100.30
56@99.90 -- 51@100.30
58@99.90 -- 4@100.40
49@99.80 -- 25@100.40
8@99.80 -- 32@100.50
38@99.80 -- 62@100.50
20@99.80 -- 36@100.50
15@99.70 -- 19@100.60
64@99.70 -- 45@100.60
7@99.70 -- 85@100.70
20@99.60 -- 96@100.70
99@99.60 -- 94@100.90
71@99.50 -- 28@100.90
93@99.40 -- 67@100.90
41@99.20 -- 69@101.10
30@99.20 -- 
6@99.20 -- 
75@99.10 -- 
5@99.00 -- 

Processing completed at: 2023-11-07 22:46:26.956950
Processing Duration: 0:00:15.601459 seconds
